<?xml version="1.0"?>
<robot name="my_robo1" xmlns:xacro="http://ros.org/wiki/xacro">
<!-- Defining properties -->
<xacro:property name="wheel_radius" value="0.05"/>
<xacro:property name="wheel_width" value="0.02"/>
<xacro:property name="body_length" value="0.4"/>
<xacro:property name="body_width" value="0.4"/>
<xacro:property name="body_height" value="0.1"/>
<!-- Base Link -->
<link name="base_link">
  <visual>
    <geometry>
      <box size="${body_length} ${body_width} ${body_height}"/>
    </geometry>
    <material name="blue">
      <color rgba="0 0 0.8 1"/>
    </material>
  </visual>
  <collision>
    <geometry>
      <box size="${body_length} ${body_width} ${body_height}"/>
    </geometry>
  </collision>
  <inertial>
    <mass value="5.0"/>
    <inertia ixx="0.1" ixy="0.0" ixz="0.0" iyy="0.1" iyz="0.0" izz="0.1"/>
  </inertial>
</link>
<!--macro to define a wheel -->
<xacro:macro name="wheel" params="name x y">
  <link name="${name}_link">
    <visual>
      <origin rpy="1.5708 0 0"/>      
      <geometry>
        <cylinder radius="${wheel_radius}" length="${wheel_width}"/>
      </geometry>
    </visual>
    <collision>
      <origin rpy="1.5708 0 0"/>
      <geometry> 
        <cylinder radius="${wheel_radius}" length="${wheel_width}"/>
      </geometry>
    </collision>
    <inertial>
      <mass value="0.1"/>
      <inertia ixx="0.0001" ixy="0.0" ixz="0.0" iyy="0.0001" iyz="0.0" izz="0.0001"/>
    </inertial>
  </link>
  <joint name="${name}_joint" type="continuous">
    <parent link="base_link"/>
    <child link="${name}_link"/>
    <origin xyz="${x} ${y} -0.15" rpy="0 0 0"/>
    <axis xyz="0 1 0"/>
  </joint>
</xacro:macro>
<!-- using macro to create 4 wheels -->
<xacro.wheel name="front_left_wheel" x="-0.2" y="0.2"/>
<xacro.wheel name="front_right_wheel" x="0.2" y="0.2"/>
<xacro.wheel name="back_left_wheel" x="-0.2" y="-0.2"/>
<xacro.wheel name="back_right_wheel" x="0.2" y="-0.2"/>
</robot>
